Unhandled exception in thread started by <function wrapper at 0x7f88ad6ce050>
Performing system checks...

Traceback (most recent call last):
  File "/usr/local/python2.7/lib/python2.7/site-packages/Django-1.10.4-py2.7.egg/django/utils/autoreload.py", line 226, in wrapper
    fn(*args, **kwargs)
  File "/usr/local/python2.7/lib/python2.7/site-packages/Django-1.10.4-py2.7.egg/django/core/management/commands/runserver.py", line 121, in inner_run
    self.check(display_num_errors=True)
  File "/usr/local/python2.7/lib/python2.7/site-packages/Django-1.10.4-py2.7.egg/django/core/management/base.py", line 374, in check
    include_deployment_checks=include_deployment_checks,
  File "/usr/local/python2.7/lib/python2.7/site-packages/Django-1.10.4-py2.7.egg/django/core/management/base.py", line 361, in _run_checks
    return checks.run_checks(**kwargs)
  File "/usr/local/python2.7/lib/python2.7/site-packages/Django-1.10.4-py2.7.egg/django/core/checks/registry.py", line 81, in run_checks
    new_errors = check(app_configs=app_configs)
  File "/usr/local/python2.7/lib/python2.7/site-packages/Django-1.10.4-py2.7.egg/django/core/checks/model_checks.py", line 30, in check_all_models
    errors.extend(model.check(**kwargs))
  File "/usr/local/python2.7/lib/python2.7/site-packages/Django-1.10.4-py2.7.egg/django/db/models/base.py", line 1266, in check
    errors.extend(cls._check_fields(**kwargs))
  File "/usr/local/python2.7/lib/python2.7/site-packages/Django-1.10.4-py2.7.egg/django/db/models/base.py", line 1337, in _check_fields
    errors.extend(field.check(**kwargs))
  File "/usr/local/python2.7/lib/python2.7/site-packages/Django-1.10.4-py2.7.egg/django/db/models/fields/__init__.py", line 893, in check
    errors = super(AutoField, self).check(**kwargs)
  File "/usr/local/python2.7/lib/python2.7/site-packages/Django-1.10.4-py2.7.egg/django/db/models/fields/__init__.py", line 208, in check
    errors.extend(self._check_backend_specific_checks(**kwargs))
  File "/usr/local/python2.7/lib/python2.7/site-packages/Django-1.10.4-py2.7.egg/django/db/models/fields/__init__.py", line 311, in _check_backend_specific_checks
    return connections[db].validation.check_field(self, **kwargs)
  File "/usr/local/python2.7/lib/python2.7/site-packages/Django-1.10.4-py2.7.egg/django/db/backends/mysql/validation.py", line 41, in check_field
    field_type = field.db_type(connection)
  File "/usr/local/python2.7/lib/python2.7/site-packages/Django-1.10.4-py2.7.egg/django/db/models/fields/__init__.py", line 629, in db_type
    return connection.data_types[self.get_internal_type()] % data
  File "/usr/local/python2.7/lib/python2.7/site-packages/Django-1.10.4-py2.7.egg/django/db/__init__.py", line 33, in __getattr__
    return getattr(connections[DEFAULT_DB_ALIAS], item)
  File "/usr/local/python2.7/lib/python2.7/site-packages/Django-1.10.4-py2.7.egg/django/utils/functional.py", line 35, in __get__
    res = instance.__dict__[self.name] = self.func(instance)
  File "/usr/local/python2.7/lib/python2.7/site-packages/Django-1.10.4-py2.7.egg/django/db/backends/mysql/base.py", line 183, in data_types
    if self.features.supports_microsecond_precision:
  File "/usr/local/python2.7/lib/python2.7/site-packages/Django-1.10.4-py2.7.egg/django/utils/functional.py", line 35, in __get__
    res = instance.__dict__[self.name] = self.func(instance)
  File "/usr/local/python2.7/lib/python2.7/site-packages/Django-1.10.4-py2.7.egg/django/db/backends/mysql/features.py", line 54, in supports_microsecond_precision
    return self.connection.mysql_version >= (5, 6, 4) and Database.version_info >= (1, 2, 5)
  File "/usr/local/python2.7/lib/python2.7/site-packages/Django-1.10.4-py2.7.egg/django/utils/functional.py", line 35, in __get__
    res = instance.__dict__[self.name] = self.func(instance)
  File "/usr/local/python2.7/lib/python2.7/site-packages/Django-1.10.4-py2.7.egg/django/db/backends/mysql/base.py", line 367, in mysql_version
    with self.temporary_connection() as cursor:
  File "/usr/local/python2.7/lib/python2.7/contextlib.py", line 17, in __enter__
    return self.gen.next()
  File "/usr/local/python2.7/lib/python2.7/site-packages/Django-1.10.4-py2.7.egg/django/db/backends/base/base.py", line 564, in temporary_connection
    cursor = self.cursor()
  File "/usr/local/python2.7/lib/python2.7/site-packages/Django-1.10.4-py2.7.egg/django/db/backends/base/base.py", line 231, in cursor
    cursor = self.make_debug_cursor(self._cursor())
  File "/usr/local/python2.7/lib/python2.7/site-packages/Django-1.10.4-py2.7.egg/django/db/backends/base/base.py", line 204, in _cursor
    self.ensure_connection()
  File "/usr/local/python2.7/lib/python2.7/site-packages/Django-1.10.4-py2.7.egg/django/db/backends/base/base.py", line 199, in ensure_connection
    self.connect()
  File "/usr/local/python2.7/lib/python2.7/site-packages/Django-1.10.4-py2.7.egg/django/db/utils.py", line 94, in __exit__
    six.reraise(dj_exc_type, dj_exc_value, traceback)
  File "/usr/local/python2.7/lib/python2.7/site-packages/Django-1.10.4-py2.7.egg/django/db/backends/base/base.py", line 199, in ensure_connection
    self.connect()
  File "/usr/local/python2.7/lib/python2.7/site-packages/Django-1.10.4-py2.7.egg/django/db/backends/base/base.py", line 171, in connect
    self.connection = self.get_new_connection(conn_params)
  File "/usr/local/python2.7/lib/python2.7/site-packages/Django-1.10.4-py2.7.egg/django/db/backends/mysql/base.py", line 263, in get_new_connection
    conn = Database.connect(**conn_params)
  File "/usr/local/python2.7/lib/python2.7/site-packages/MySQL_python-1.2.3c1-py2.7-linux-x86_64.egg/MySQLdb/__init__.py", line 81, in Connect
  File "/usr/local/python2.7/lib/python2.7/site-packages/MySQL_python-1.2.3c1-py2.7-linux-x86_64.egg/MySQLdb/connections.py", line 188, in __init__
django.db.utils.OperationalError: (1193, "Unknown system variable 'sql_model'")
Unhandled exception in thread started by <function wrapper at 0x7f8539e79050>
Performing system checks...

Traceback (most recent call last):
  File "/usr/local/python2.7/lib/python2.7/site-packages/Django-1.10.4-py2.7.egg/django/utils/autoreload.py", line 226, in wrapper
    fn(*args, **kwargs)
  File "/usr/local/python2.7/lib/python2.7/site-packages/Django-1.10.4-py2.7.egg/django/core/management/commands/runserver.py", line 121, in inner_run
    self.check(display_num_errors=True)
  File "/usr/local/python2.7/lib/python2.7/site-packages/Django-1.10.4-py2.7.egg/django/core/management/base.py", line 374, in check
    include_deployment_checks=include_deployment_checks,
  File "/usr/local/python2.7/lib/python2.7/site-packages/Django-1.10.4-py2.7.egg/django/core/management/base.py", line 361, in _run_checks
    return checks.run_checks(**kwargs)
  File "/usr/local/python2.7/lib/python2.7/site-packages/Django-1.10.4-py2.7.egg/django/core/checks/registry.py", line 81, in run_checks
    new_errors = check(app_configs=app_configs)
  File "/usr/local/python2.7/lib/python2.7/site-packages/Django-1.10.4-py2.7.egg/django/core/checks/model_checks.py", line 30, in check_all_models
    errors.extend(model.check(**kwargs))
  File "/usr/local/python2.7/lib/python2.7/site-packages/Django-1.10.4-py2.7.egg/django/db/models/base.py", line 1266, in check
    errors.extend(cls._check_fields(**kwargs))
  File "/usr/local/python2.7/lib/python2.7/site-packages/Django-1.10.4-py2.7.egg/django/db/models/base.py", line 1337, in _check_fields
    errors.extend(field.check(**kwargs))
  File "/usr/local/python2.7/lib/python2.7/site-packages/Django-1.10.4-py2.7.egg/django/db/models/fields/__init__.py", line 893, in check
    errors = super(AutoField, self).check(**kwargs)
  File "/usr/local/python2.7/lib/python2.7/site-packages/Django-1.10.4-py2.7.egg/django/db/models/fields/__init__.py", line 208, in check
    errors.extend(self._check_backend_specific_checks(**kwargs))
  File "/usr/local/python2.7/lib/python2.7/site-packages/Django-1.10.4-py2.7.egg/django/db/models/fields/__init__.py", line 311, in _check_backend_specific_checks
    return connections[db].validation.check_field(self, **kwargs)
  File "/usr/local/python2.7/lib/python2.7/site-packages/Django-1.10.4-py2.7.egg/django/db/backends/mysql/validation.py", line 41, in check_field
    field_type = field.db_type(connection)
  File "/usr/local/python2.7/lib/python2.7/site-packages/Django-1.10.4-py2.7.egg/django/db/models/fields/__init__.py", line 629, in db_type
    return connection.data_types[self.get_internal_type()] % data
  File "/usr/local/python2.7/lib/python2.7/site-packages/Django-1.10.4-py2.7.egg/django/db/__init__.py", line 33, in __getattr__
    return getattr(connections[DEFAULT_DB_ALIAS], item)
  File "/usr/local/python2.7/lib/python2.7/site-packages/Django-1.10.4-py2.7.egg/django/utils/functional.py", line 35, in __get__
    res = instance.__dict__[self.name] = self.func(instance)
  File "/usr/local/python2.7/lib/python2.7/site-packages/Django-1.10.4-py2.7.egg/django/db/backends/mysql/base.py", line 183, in data_types
    if self.features.supports_microsecond_precision:
  File "/usr/local/python2.7/lib/python2.7/site-packages/Django-1.10.4-py2.7.egg/django/utils/functional.py", line 35, in __get__
    res = instance.__dict__[self.name] = self.func(instance)
  File "/usr/local/python2.7/lib/python2.7/site-packages/Django-1.10.4-py2.7.egg/django/db/backends/mysql/features.py", line 54, in supports_microsecond_precision
    return self.connection.mysql_version >= (5, 6, 4) and Database.version_info >= (1, 2, 5)
  File "/usr/local/python2.7/lib/python2.7/site-packages/Django-1.10.4-py2.7.egg/django/utils/functional.py", line 35, in __get__
    res = instance.__dict__[self.name] = self.func(instance)
  File "/usr/local/python2.7/lib/python2.7/site-packages/Django-1.10.4-py2.7.egg/django/db/backends/mysql/base.py", line 367, in mysql_version
    with self.temporary_connection() as cursor:
  File "/usr/local/python2.7/lib/python2.7/contextlib.py", line 17, in __enter__
    return self.gen.next()
  File "/usr/local/python2.7/lib/python2.7/site-packages/Django-1.10.4-py2.7.egg/django/db/backends/base/base.py", line 564, in temporary_connection
    cursor = self.cursor()
  File "/usr/local/python2.7/lib/python2.7/site-packages/Django-1.10.4-py2.7.egg/django/db/backends/base/base.py", line 231, in cursor
    cursor = self.make_debug_cursor(self._cursor())
  File "/usr/local/python2.7/lib/python2.7/site-packages/Django-1.10.4-py2.7.egg/django/db/backends/base/base.py", line 204, in _cursor
    self.ensure_connection()
  File "/usr/local/python2.7/lib/python2.7/site-packages/Django-1.10.4-py2.7.egg/django/db/backends/base/base.py", line 199, in ensure_connection
    self.connect()
  File "/usr/local/python2.7/lib/python2.7/site-packages/Django-1.10.4-py2.7.egg/django/db/utils.py", line 94, in __exit__
    six.reraise(dj_exc_type, dj_exc_value, traceback)
  File "/usr/local/python2.7/lib/python2.7/site-packages/Django-1.10.4-py2.7.egg/django/db/backends/base/base.py", line 199, in ensure_connection
    self.connect()
  File "/usr/local/python2.7/lib/python2.7/site-packages/Django-1.10.4-py2.7.egg/django/db/backends/base/base.py", line 171, in connect
    self.connection = self.get_new_connection(conn_params)
  File "/usr/local/python2.7/lib/python2.7/site-packages/Django-1.10.4-py2.7.egg/django/db/backends/mysql/base.py", line 263, in get_new_connection
    conn = Database.connect(**conn_params)
  File "/usr/local/python2.7/lib/python2.7/site-packages/MySQL_python-1.2.3c1-py2.7-linux-x86_64.egg/MySQLdb/__init__.py", line 81, in Connect
  File "/usr/local/python2.7/lib/python2.7/site-packages/MySQL_python-1.2.3c1-py2.7-linux-x86_64.egg/MySQLdb/connections.py", line 188, in __init__
django.db.utils.OperationalError: (1193, "Unknown system variable 'sql_model'")
Error: That port is already in use.
[?1034hAn exception has occurred, use %tb to see the full traceback.

[1;31mSystemExit[0m[1;31m:[0m 1

